<?xml version='1.0' encoding='utf-8'?>
<robot xmlns:xacro="http://www.ros.org/wiki/xacro" name="franka_pendulum">
  <xacro:arg name="arm_id" default="panda" />
  <xacro:arg name="friction" default="false" />
  
  <!-- Create a simulatable URDF -->
  <xacro:include filename="$(find franka_description)/robots/utils.xacro" />
  <xacro:unless value="$(arg friction)">
    <xacro:include filename="$(find franka_description)/robots/panda_gazebo.xacro" />
  </xacro:unless>
  <xacro:if value="$(arg friction)">
    <xacro:include filename="$(find franka_pendulum)/robots/panda_gazebo.xacro" />
  </xacro:if>
  <xacro:panda_arm arm_id="$(arg arm_id)" />
  <xacro:hand arm_id="$(arg arm_id)" rpy="0 0 ${-pi/4}" connected_to="$(arg arm_id)_link8" />
  <xacro:gazebo-joint joint="$(arg arm_id)_finger_joint1" transmission="hardware_interface/EffortJointInterface" />
  <xacro:gazebo-joint joint="$(arg arm_id)_finger_joint2" transmission="hardware_interface/EffortJointInterface" />
  
  <!-- Gazebo requires a joint to a link called "world" for statically mounted robots -->
  <link name="world" />
    <joint name="world_joint" type="fixed">
    <origin xyz="0 0 0" rpy="0 0 0" />
    <parent link="world" />
    <child  link="$(arg arm_id)_link0" />
  </joint>
  <xacro:gazebo-joint joint="$(arg arm_id)_joint1" transmission="hardware_interface/EffortJointInterface" />
  <xacro:gazebo-joint joint="$(arg arm_id)_joint2" transmission="hardware_interface/EffortJointInterface" />
  <xacro:gazebo-joint joint="$(arg arm_id)_joint3" transmission="hardware_interface/EffortJointInterface" />
  <xacro:gazebo-joint joint="$(arg arm_id)_joint4" transmission="hardware_interface/EffortJointInterface" />
  <xacro:gazebo-joint joint="$(arg arm_id)_joint5" transmission="hardware_interface/EffortJointInterface" />
  <xacro:gazebo-joint joint="$(arg arm_id)_joint6" transmission="hardware_interface/EffortJointInterface" />
  <xacro:gazebo-joint joint="$(arg arm_id)_joint7" transmission="hardware_interface/EffortJointInterface" />
  <xacro:transmission-franka-state arm_id="$(arg arm_id)" />
  <xacro:transmission-franka-model arm_id="$(arg arm_id)" root="$(arg arm_id)_joint1" tip="$(arg arm_id)_joint8" />

  <gazebo>
    <plugin name="gazebo_ros_control" filename="libgazebo_ros_control.so">
      <controlPeriod>0.001</controlPeriod>
      <robotSimType>franka_gazebo/FrankaHWSim</robotSimType>
    </plugin>
    <plugin name="franka_pendulum_plugin" filename="libfranka_pendulum_plugin.so">
    </plugin>
    <self_collide>true</self_collide>
  </gazebo>

  <!-- Connection -->   
  <joint name="$(arg arm_id)_pendulum_joint_connection" type="fixed">
    <origin xyz="${0.110/sqrt(2)} -${0.110/sqrt(2)} 0.03" rpy="${pi} 0 ${-pi/4}" />
    <parent link="$(arg arm_id)_link8" />
    <child  link="$(arg arm_id)_pendulum_link_lower" />
  </joint>
  
  <!-- Lower bearing -->
  <link name="$(arg arm_id)_pendulum_link_lower">
    <visual>
      <origin xyz="0 0 0" rpy="0 0 0"/>
      <geometry>
        <mesh filename="package://franka_pendulum/meshes/visual/2D_lower.dae"/>
      </geometry>
    </visual>

    <inertial>
      <origin xyz="-0.05417692376165083 1.631629415101512e-05 -0.10102516335402327" rpy="0 0 0"/>
      <mass value="0.42122634375995777"/>
      <inertia
      ixx="0.0009355660559119161" ixy="-1.919376506548452e-07" ixz="-0.00024073219427997694"
      iyy="0.0014466958209361893" iyz="-3.8184740643923794e-07"
      izz="0.0009820861200053165"/>
    </inertial>
  </link>
  
  <joint name="$(arg arm_id)_pendulum_joint_y" type="revolute">
    <parent link="$(arg arm_id)_pendulum_link_lower"/>
    <child link="$(arg arm_id)_pendulum_link_middle"/>
    <origin xyz="0 0 0" rpy="0 0 0"/>
    <axis xyz="0 1 0"/>
    <limit velocity="1000000" lower="${0*pi/180}" effort="0" upper="${60*pi/180}" />
    <dynamics damping="0.0"/>
  </joint>

  <!-- Middle bearing -->
  <link name="$(arg arm_id)_pendulum_link_middle">
    <visual>
      <origin xyz="0 0 0" rpy="0 0 0"/>
      <geometry>
        <mesh filename="package://franka_pendulum/meshes/visual/2D_middle.dae"/>
      </geometry>
    </visual>

    <inertial>
      <origin xyz="0.0 6.359054534633294e-09 0.006000000469716085" rpy="0 0 0"/>
      <mass value="0.01583948395827795"/>
      <inertia
      ixx="5.652102918535614e-06" ixy="0.0" ixz="0.0"
      iyy="5.652102918535616e-06" iyz="0.0"
      izz="4.031806214159512e-06"/>
    </inertial>
  </link>
  
  <joint name="$(arg arm_id)_pendulum_joint_x" type="revolute">
    <parent link="$(arg arm_id)_pendulum_link_middle"/>
    <child link="$(arg arm_id)_pendulum_link_upper"/>
    <origin xyz="0 0 0.012" rpy="0 0 0"/>
    <axis xyz="1 0 0"/>
    <limit velocity="1000000" lower="${-30*pi/180}" effort="0" upper="${30*pi/180}" />
    <dynamics damping="0.0"/>
  </joint>
  
  <!-- Upper bearing, beam and ball -->
  <link name="$(arg arm_id)_pendulum_link_upper">
    <visual>
      <origin xyz="0 0 -0.012" rpy="0 0 0"/>
      <geometry>
        <mesh filename="package://franka_pendulum/meshes/visual/2D_upper.dae"/>
      </geometry>
    </visual>
    <visual>
      <origin xyz="0 0 ${0.06 + 0.65/2}" rpy="0 0 0"/>
      <geometry>
        <cylinder length="0.65" radius="0.005"/>
      </geometry>
    </visual>
    <visual>
      <origin xyz="0 0 0.43" rpy="0 0 0"/>
      <geometry>
        <sphere radius="0.0275"/>
      </geometry>
    </visual>
    
    <inertial>
      <origin xyz="-6.25914508960298e-05 2.6377566995216277e-07 ${0.18536862521254435 - 0.012}" rpy="0 0 0"/>
      <mass value="0.13492793369531808"/>
      <inertia
      ixx="0.005252713974715477" ixy="0.0" ixz="-1.0207840204095797e-06"
      iyy="0.005226062508314185" iyz="5.116218503426479e-09"
      izz="0.00014648155653184902"/>
    </inertial>
  </link>
  
  <transmission name="$(arg arm_id)_pendulum_joint_y_transmission">
    <type>transmission_interface/SimpleTransmission</type>
    <joint name="$(arg arm_id)_pendulum_joint_y">
      <hardwareInterface>hardware_interface/PositionJointInterface</hardwareInterface>
    </joint>
    <actuator name="$(arg arm_id)_pendulum_joint_y_motor">
      <hardwareInterface>hardware_interface/PositionJointInterface</hardwareInterface>
    </actuator>
  </transmission>
  <transmission name="$(arg arm_id)_pendulum_joint_x_transmission">
    <type>transmission_interface/SimpleTransmission</type>
    <joint name="$(arg arm_id)_pendulum_joint_x">
      <hardwareInterface>hardware_interface/PositionJointInterface</hardwareInterface>
    </joint>
    <actuator name="$(arg arm_id)_pendulum_joint_x_motor">
      <hardwareInterface>hardware_interface/PositionJointInterface</hardwareInterface>
    </actuator>
  </transmission>
</robot>
